Workbook

Sheet грязная
B1: СЕНТЯБРЬ
A3: Машина | B3: АМУР-ЭП | E3: ЭС+
B4: час | C4: цена | D4: сумма | E4: час | F4: цена | G4: сумма
A5: 110 | B5: 80 | C5: 3500 | D5: =B5*C5 -> 280000 | E5: 40 | F5: 3500 | G5: =E5*F5 -> 140000
A6: 168 служебная | B6: 220 | C6: 1000 | D6: =B6*C6 -> 220000 | G6: =E6*F6 -> 0
A7: 185 груз.самосвал | B7: 136 | C7: 3500 | D7: =B7*C7 -> 476000 | G7: =E7*F7 -> 0
A8: 187 груз.с краном | B8: 40 | C8: 3500 | D8: =B8*C8 -> 140000 | E8: 96 | F8: 3500 | G8: =E8*F8 -> 336000
A9: 254 бур-кран+перевоз опор | B9: 32 | C9: 3500 | D9: =B9*C9 -> 112000 | E9: 46 | F9: 3500 | G9: =E9*F9 -> 161000
A10: 278 2-х кабин.грузовая | B10: 32 | C10: 1000 | D10: =B10*C10 -> 32000 | G10: =E10*F10 -> 0
A11: 301 бур-кран с автовышк. | B11: 26.5 | C11: 3000 | D11: =B11*C11 -> 79500 | G11: =E11*F11 -> 0
A12: 417 авто-вышка | B12: 129.5 | C12: 2500 | D12: =B12*C12 -> 323750 | E12: 16.5 | F12: 2500 | G12: =E12*F12 -> 41250
A13: 498 бур-кран,автовышк | B13: 57 | C13: 3000 | D13: =B13*C13 -> 171000 | E13: 24 | F13: 3000 | G13: =E13*F13 -> 72000
A14: 629 урал бур-кран | B14: 5 | C14: 4000 | D14: =B14*C14 -> 20000 | G14: =E14*F14 -> 0
A15: 703 бур-кран с автовышк | B15: 18 | C15: 4000 | D15: =B15*C15 -> 72000 | G15: =E15*F15 -> 0
A16: 762 служебная | B16: 40.5 | C16: 1000 | D16: =B16*C16 -> 40500 | E16: 24 | F16: 1000 | G16: =E16*F16 -> 24000
A17: 816 груз.с краном | B17: 24 | C17: 2500 | D17: =B17*C17 -> 60000 | G17: =E17*F17 -> 0
A18: буровая гусеничн | C18: 4000 | D18: =B18*C18 -> 0 | E18: 13 | F18: 4000 | G18: =E18*F18 -> 52000
A19: дт75 | B19: 8 | C19: 3500 | D19: =B19*C19 -> 28000 | E19: 8 | F19: 3500 | G19: =E19*F19 -> 28000
A20: эксковатор | B20: 24 | C20: 2000 | D20: =B20*C20 -> 48000 | E20: 7.5 | F20: 2000 | G20: =E20*F20 -> 15000
A21: ханикс | D21: =B21*C21 -> 0 | G21: =E21*F21 -> 0
A22: ИТОГО | B22: =SUM(B5:B21) -> 872.5 | D22: =SUM(D5:D21) -> 2102750 | E22: =SUM(E5:E21) -> 275 | G22: =SUM(G5:G21) -> 869250
B24: ОКТЯБРЬ
A27: Машина | B27: АМУР-ЭП | E27: ЭС+
B28: час | C28: цена | D28: сумма | E28: час | F28: цена | G28: сумма
A29: 110 | B29: 80 | C29: 3500 | D29: =B29*C29 -> 280000 | E29: 56 | F29: 3500 | G29: =E29*F29 -> 196000
A30: 168 служебная | B30: 230 | C30: 1000 | D30: =B30*C30 -> 230000 | F30: 1000 | G30: =E30*F30 -> 0
A31: 185 груз.самосвал | B31: 120 | C31: 3500 | D31: =B31*C31 -> 420000 | F31: 3500 | G31: =E31*F31 -> 0
A32: 187 груз.с краном | B32: 72 | C32: 3500 | D32: =B32*C32 -> 252000 | E32: 16 | F32: 3500 | G32: =E32*F32 -> 56000
A33: 254 бур-кран+перевоз опор | B33: 94 | C33: 3500 | D33: =B33*C33 -> 329000 | E33: 25 | F33: 3500 | G33: =E33*F33 -> 87500
A34: 278 2-х кабин.грузовая | B34: 110.5 | C34: 1000 | D34: =B34*C34 -> 110500 | F34: 1000 | G34: =E34*F34 -> 0
A35: 301 бур-кран с автовышк. | C35: 3000 | D35: =B35*C35 -> 0 | F35: 3000 | G35: =E35*F35 -> 0
A36: 417 авто-вышка | B36: 111.5 | C36: 2500 | D36: =B36*C36 -> 278750 | E36: 28 | F36: 2500 | G36: =E36*F36 -> 70000
A37: 498 бур-кран,автовышк | B37: 21 | C37: 3000 | D37: =B37*C37 -> 63000 | F37: 3000 | G37: =E37*F37 -> 0
A38: 629 урал бур-кран | C38: 4000 | D38: =B38*C38 -> 0 | F38: 4000 | G38: =E38*F38 -> 0
A39: 703 бур-кран с автовышк | B39: 16 | C39: 4000 | D39: =B39*C39 -> 64000 | E39: 10 | F39: 4000 | G39: =E39*F39 -> 40000
A40: 762 служебная | B40: 88 | C40: 1000 | D40: =B40*C40 -> 88000 | E40: 82 | F40: 1000 | G40: =E40*F40 -> 82000
A41: 816 груз.с краном | C41: 2500 | D41: =B41*C41 -> 0 | F41: 2500 | G41: =E41*F41 -> 0
A42: буровая гусеничн | B42: 6.5 | C42: 4000 | D42: =B42*C42 -> 26000 | F42: 4000 | G42: =E42*F42 -> 0
A43: дт75 | C43: 3500 | D43: =B43*C43 -> 0 | F43: 3500 | G43: =E43*F43 -> 0
A44: эксковатор | B44: 15 | C44: 2000 | D44: =B44*C44 -> 30000 | F44: 2000 | G44: =E44*F44 -> 0
...

Sheet чистая
B1: СЕНТЯБРЬ
A3: Машина | B3: АМУР-ЭП | E3: ЭС+
B4: час | C4: цена | D4: сумма | E4: час | F4: цена | G4: сумма
A5: 110 | B5: 80 | C5: 3500 | D5: =B5*C5 -> 280000 | E5: 40 | F5: 3500 | G5: =E5*F5 -> 140000
A6: 168 служебная | B6: 220 | C6: 1000 | D6: =B6*C6 -> 220000 | G6: =E6*F6 -> 0
A7: 185 груз.самосвал | B7: 136 | C7: 3500 | D7: =B7*C7 -> 476000 | G7: =E7*F7 -> 0
A8: 187 груз.с краном | B8: 40 | C8: 3500 | D8: =B8*C8 -> 140000 | E8: 96 | F8: 3500 | G8: =E8*F8 -> 336000
A9: 254 бур-кран+перевоз опор | B9: 32 | C9: 3500 | D9: =B9*C9 -> 112000 | E9: 46 | F9: 3500 | G9: =E9*F9 -> 161000
A10: 278 2-х кабин.грузовая | B10: 32 | C10: 1000 | D10: =B10*C10 -> 32000 | G10: =E10*F10 -> 0
A11: 301 бур-кран с автовышк. | B11: 26.5 | C11: 3000 | D11: =B11*C11 -> 79500 | G11: =E11*F11 -> 0
A12: 417 авто-вышка | B12: 129.5 | C12: 2500 | D12: =B12*C12 -> 323750 | E12: 16.5 | F12: 2500 | G12: =E12*F12 -> 41250
A13: 498 бур-кран,автовышк | B13: 57 | C13: 3000 | D13: =B13*C13 -> 171000 | E13: 24 | F13: 3000 | G13: =E13*F13 -> 72000
A14: 629 урал бур-кран | B14: 5 | C14: 4000 | D14: =B14*C14 -> 20000 | G14: =E14*F14 -> 0
A15: 703 бур-кран с автовышк | B15: 18 | C15: 4000 | D15: =B15*C15 -> 72000 | G15: =E15*F15 -> 0
A16: 762 служебная | B16: 40.5 | C16: 1000 | D16: =B16*C16 -> 40500 | E16: 24 | F16: 1000 | G16: =E16*F16 -> 24000
A17: 816 груз.с краном | B17: 24 | C17: 2500 | D17: =B17*C17 -> 60000 | G17: =E17*F17 -> 0
A18: буровая гусеничн | C18: 4000 | D18: =B18*C18 -> 0 | E18: 13 | F18: 4000 | G18: =E18*F18 -> 52000
A19: дт75 | B19: 8 | C19: 3500 | D19: =B19*C19 -> 28000 | E19: 8 | F19: 3500 | G19: =E19*F19 -> 28000
A20: эксковатор | B20: 24 | C20: 2000 | D20: =B20*C20 -> 48000 | E20: 7.5 | F20: 2000 | G20: =E20*F20 -> 15000
A21: ханикс | D21: =B21*C21 -> 0 | G21: =E21*F21 -> 0
A22: ИТОГО | B22: =SUM(B5:B21) -> 872.5 | D22: =SUM(D5:D21) -> 2102750 | E22: =SUM(E5:E21) -> 275 | G22: =SUM(G5:G21) -> 869250
B24: ОКТЯБРЬ
A25: Машина | B25: АМУР-ЭП | C25: Леонов | E25: ЭС+ | H25: ЭС+ | I25: дата | J25: ч | K25: сумма | N25: ФИО | O25: л | P25: км | Q25: сумма
B26: час | C26: цена | D26: сумма | E26: час | F26: цена | G26: сумма | I26: Амур-эп с сентября учтен в окт | N26: Крымов | O26: 204 | P26: 1360 | Q26: 12878
A27: 110 | B27: 80 | C27: 3500 | D27: =B27*C27 -> 280000 | E27: 56 | F27: 3500 | G27: =E27*F27 -> 196000 | N27: Черкасская | O27: 186 | P27: 1240 | Q27: 11500
A28: 168 служебная | B28: 252 | C28: 1000 | D28: =B28*C28 -> 252000 | F28: 1000 | G28: =E28*F28 -> 0 | N28: Трунин | O28: 130 | P28: 866 | Q28: 9943
A29: 185 груз.самосвал | B29: 208 | C29: 3500 | D29: =B29*C29 -> 728000 | F29: 3500 | G29: =E29*F29 -> 0 | I29: 25-31.09 | J29: 32 | K29: 112000 | N29: Шулико | O29: 90 | P29: 600 | Q29: 6063
A30: 187 груз.с краном | B30: 104 | C30: 3500 | D30: =B30*C30 -> 364000 | E30: 48 | F30: 3500 | G30: =E30*F30 -> 168000 | I30: 25-31.09 | J30: 16 | K30: 56000 | N30: Некрутов | O30: 77 | P30: 513 | Q30: 4999
A31: 254 бур-кран+перевоз опор | B31: 142 | C31: 3500 | D31: =B31*C31 -> 497000 | E31: 49 | F31: 3500 | G31: =E31*F31 -> 171500 | I31: 25-31,09 | J31: 24 | K31: 84000 | N31: Богатырев | O31: 170 | P31: 1133 | Q31: 12400
A32: 278 2-х кабин.грузовая | B32: 126.5 | C32: 1000 | D32: =B32*C32 -> 126500 | F32: 1000 | G32: =E32*F32 -> 0 | N32: 168 служебная | O32: 230
A33: 301 бур-кран с автовышк. | B33: 26.5 | C33: 3000 | D33: =B33*C33 -> 79500 | F33: 3000 | G33: =E33*F33 -> 0 | I33: 01-31.09 | J33: 26.5 | K33: 79500
A34: 417 авто-вышка | B34: 135.6 | C34: 2500 | D34: =B34*C34 -> 339000 | E34: 53 | F34: 2500 | G34: =E34*F34 -> 132500 | I34: 25-31,09 | J34: 25 | K34: 62500
A35: 498 бур-кран,автовышк | B35: 101 | C35: 3000 | D35: =B35*C35 -> 303000 | F35: 3000 | G35: =E35*F35 -> 0
A36: 629 урал бур-кран | C36: 4000 | D36: =B36*C36 -> 0 | F36: 4000 | G36: =E36*F36 -> 0
A37: 703 бур-кран с автовышк | B37: 88 | C37: 4000 | D37: =B37*C37 -> 352000 | E37: 59 | F37: 4000 | G37: =E37*F37 -> 236000
A38: 762 служебная | B38: 88 | C38: 1000 | D38: =B38*C38 -> 88000 | E38: 82 | F38: 1000 | G38: =E38*F38 -> 82000
A39: 816 груз.с краном | C39: 2500 | D39: =B39*C39 -> 0 | F39: 2500 | G39: =E39*F39 -> 0 | Q39: НДС
A40: буровая гусеничн | B40: 6.5 | C40: 4000 | D40: =B40*C40 -> 26000 | F40: 4000 | G40: =E40*F40 -> 0 | O40: ОКТЯБРЬ | V40: забирали с сентября
A41: дт75 | B41: 22 | C41: 3500 | D41: =B41*C41 -> 77000 | E41: 29 | F41: 3500 | G41: =E41*F41 -> 101500 | N41: Машина | O41: АМУР-ЭП | P41: Леонов | R41: ЭС+ | U41: ЭС+ | V41: дата | W41: ч | X41: сумма
A42: эксковатор | B42: 73 | C42: 2000 | D42: =B42*C42 -> 146000 | F42: 2000 | G42: =E42*F42 -> 0 | I42: 01-30.09 | J42: 24 | K42: 48000 | O42: час | P42: цена | Q42: сумма | R42: час | S42: цена | T42: сумма | V42: Амур-эп с сентября учтен в окт
...

Sheet Сводка
F1: 6750000
C2: ЯНВАРЬ | F2: =C6+I6+E6+K6+O6+Q6 -> 8457800 | I2: ФЕВРАЛЬ | O2: МАРТ
C3: АМУР-ЭП | E3: ЭС+ | F3: =F1/F2 -> 0.79807988 | I3: АМУР-ЭП | K3: ЭС+ | O3: АМУР-ЭП | Q3: ЭС+
B4: ФАКТ | C4: ='01.26'!N26 -> 2311075 | E4: ='01.26'!Q25 -> 28000 | H4: ФАКТ | I4: ='02.26'!M26 -> 2114200 | K4: ='02.26'!P26 -> 302400 | N4: ФАКТ | O4: ='03.26 (изм)'!O29 -> 1020375 | Q4: ='03.26 (изм)'!R28 -> 389500
B5: ГСМ | C5: ='01.26'!N27 -> 1150500 | E5: ='01.26'!Q27 -> 0 | H5: ГСМ | I5: ='02.26'!M27 -> 1268500 | K5: ='02.26'!P27 -> 0 | N5: ГСМ | O5: ='03.26 (изм)'!O30 -> 49750 | Q5: ='03.26 (изм)'!R30 -> -176500
B6: Итого | C6: =C4+C5 -> 3461575 | E6: =E4+E5 -> 28000 | H6: Итого | I6: =I4+I5 -> 3382700 | K6: =K4+K5 -> 302400 | N6: Итого | O6: =O4+O5 -> 1070125 | Q6: =Q4+Q5 -> 213000
C7: ОПЛАЧЕНО | I7: ОПЛАЧЕНО | O7: ОПЛАЧЕНО
B8: №70 от 03.03 по сч. 21 | C8: 160000 | D8: №1 от 22.01 по дог. | E8: 50000 | J8: №10 от 28.01 по дог | K8: 100000 | P8: №25 от 06.02 по дог | Q8: 119560
B9: №85 от 16.03 по сч.21 | C9: 10000 | J9: №23 от 06.02 по дог | K9: 200450 | P9: №29 от 11.02 по дог | Q9: 350450
B10: №87 от 16.03 по сч.21 | C10: 10000
B11: №101от 31.03 по сч.21 | C11: 500000
B12: №120от 14.04 по сч.21 | C12: 200000
B13: №123 от 14.04 по сч.21 | C13: 50000
B14: №157 от 22.04 по сч.21 | C14: 600000
B17: Итого | C17: =SUM(C8:C16) -> 1530000 | E17: =SUM(E8:E16) -> 50000 | H17: Итого | I17: =SUM(I8:I16) -> 0 | K17: =SUM(K8:K16) -> 300450 | N17: Итого | O17: =SUM(O8:O16) -> 0 | Q17: =SUM(Q8:Q16) -> 470010
B19: ОСТАТОК | C19: =C6-C17 -> 1931575 | E19: =E6-E17 -> -22000 | H19: ОСТАТОК | I19: =I6-I17 -> 3382700 | K19: =K6-K17 -> 1950 | N19: ОСТАТОК | O19: =O6-O17 -> 1070125 | Q19: =Q6-Q17 -> -257010
B21: ИТОГО ОСТАТОК | C21: =C19+I19+O19 -> 6384400 | E21: =E19+K19+Q19 -> -277060
B23: сч№21 от 30.01 | C23: 2289075 | D23: сч№22 30.01 | E23: 28000 | H23: сч№28 от 28.02 | I23: 2964740 | J23: сч№13 от27.02 | K23: 119560 | N23: сч№30 от 31.03. | O23: 2940000 | P23: сч№29 от31.03 | Q23: 960000

Sheet 01.26 (изм)
B2: ЯНВАРЬ | D2: ВАРГА | E2: ФАКТ | L2: ЯНВАРЬ | N2: ВАРГА
A3: Машина | B3: АМУР-ЭП | C3: Леонов | E3: ЭС+ | K3: Машина | L3: АМУР-ЭП | M3: Леонов | O3: ЭС+ | R3: АМУР-ЭП | S3: Мурзин
B4: час | C4: цена | D4: сумма | E4: час | F4: цена | G4: сумма | L4: час | M4: цена | N4: сумма | O4: час | P4: цена | Q4: сумма | R4: час | S4: цена | T4: сумма
A5: 110 HINO RANGER | B5: 96 | C5: =$W$5 -> 1750 | D5: =B5*C5 -> 168000 | E5: 8 | F5: =$W$5 -> 1750 | G5: =E5*F5 -> 14000 | K5: 110 HINO RANGER | L5: 96 | M5: =$W$5 -> 1750 | N5: =L5*M5 -> 168000 | O5: 8 | P5: =$W$5 -> 1750 | Q5: =O5*P5 -> 14000 | S5: =$W$5 -> 1750 | T5: =R5*S5 -> 0 | W5: =X5 -> 1750 | X5: =Y5/2 -> 1750 | Y5: 3500
A6: 168 служебная | B6: 143 | C6: =$W$6 -> 500 | D6: =B6*C6 -> 71500 | F6: =$W$6 -> 500 | G6: =E6*F6 -> 0 | K6: 168 служебная | L6: 143 | M6: =$W$6 -> 500 | N6: =L6*M6 -> 71500 | P6: =$W$6 -> 500 | Q6: =O6*P6 -> 0 | S6: =$W$6 -> 500 | T6: =R6*S6 -> 0 | W6: =X6 -> 500 | X6: =Y6/2 -> 500 | Y6: 1000
A7: 185 груз.самосвал | B7: 88.45 | C7: =$W$7 -> 1750 | D7: =B7*C7 -> 154787.5 | F7: =$W$7 -> 1750 | G7: =E7*F7 -> 0 | K7: 185 груз.самосвал | L7: 88.45 | M7: =$W$7 -> 1750 | N7: =L7*M7 -> 154787.5 | P7: =$W$7 -> 1750 | Q7: =O7*P7 -> 0 | S7: =$W$7 -> 1750 | T7: =R7*S7 -> 0 | W7: =X7 -> 1750 | X7: =Y7/2 -> 1750 | Y7: 3500
A8: 187 груз.с краном | B8: 112 | C8: =$W$8 -> 1750 | D8: =B8*C8 -> 196000 | F8: =$W$8 -> 1750 | G8: =E8*F8 -> 0 | K8: 187 груз.с краном | L8: =112-R8 -> 76 | M8: =$W$8 -> 1750 | N8: =L8*M8 -> 133000 | P8: =$W$8 -> 1750 | Q8: =O8*P8 -> 0 | R8: 36 | S8: =$W$8 -> 1750 | T8: =R8*S8 -> 63000 | W8: =X8 -> 1750 | X8: =Y8/2 -> 1750 | Y8: 3500
A9: 254 бур-кран+перевоз опор | B9: 27 | C9: =$W$9 -> 1750 | D9: =B9*C9 -> 47250 | F9: =$W$9 -> 1750 | G9: =E9*F9 -> 0 | K9: 254 бур-кран+перевоз опор | L9: 27 | M9: =$W$9 -> 1750 | N9: =L9*M9 -> 47250 | P9: =$W$9 -> 1750 | Q9: =O9*P9 -> 0 | S9: =$W$9 -> 1750 | T9: =R9*S9 -> 0 | W9: =X9 -> 1750 | X9: =Y9/2 -> 1750 | Y9: 3500
A10: 278 2-х кабин.грузовая | B10: 24 | C10: =$W$10 -> 500 | D10: =B10*C10 -> 12000 | F10: =$W$10 -> 500 | G10: =E10*F10 -> 0 | K10: 278 2-х кабин.грузовая | L10: 24 | M10: =$W$10 -> 500 | N10: =L10*M10 -> 12000 | P10: =$W$10 -> 500 | Q10: =O10*P10 -> 0 | S10: =$W$10 -> 500 | T10: =R10*S10 -> 0 | W10: =X10 -> 500 | X10: =Y10/2 -> 500 | Y10: 1000
A11: 365 2-х кабинник | B11: 8 | C11: =$W$11 -> 500 | D11: =B11*C11 -> 4000 | F11: =$W$11 -> 500 | G11: =E11*F11 -> 0 | K11: 365 2-х кабинник | L11: 8 | M11: =$W$11 -> 500 | N11: =L11*M11 -> 4000 | P11: =$W$11 -> 500 | Q11: =O11*P11 -> 0 | S11: =$W$11 -> 500 | T11: =R11*S11 -> 0 | W11: =X11 -> 500 | X11: =Y11/2 -> 500 | Y11: 1000
A12: 344 2-х кабинник | B12: 8 | C12: =$W$12 -> 500 | D12: =B12*C12 -> 4000 | F12: =$W$12 -> 500 | G12: =E12*F12 -> 0 | K12: 344 2-х кабинник | L12: 8 | M12: =$W$12 -> 500 | N12: =L12*M12 -> 4000 | P12: =$W$12 -> 500 | Q12: =O12*P12 -> 0 | S12: =$W$12 -> 500 | T12: =R12*S12 -> 0 | W12: =X12 -> 500 | X12: =Y12/2 -> 500 | Y12: 1000
A13: 301 бур-кран с автовышк. | C13: =$W$13 -> 1750 | D13: =B13*C13 -> 0 | F13: =$W$13 -> 1750 | G13: =E13*F13 -> 0 | K13: 301 бур-кран с автовышк. | M13: =$W$13 -> 1750 | N13: =L13*M13 -> 0 | P13: =$W$13 -> 1750 | Q13: =O13*P13 -> 0 | S13: =$W$13 -> 1750 | T13: =R13*S13 -> 0 | W13: =X13 -> 1750 | X13: =Y13/2 -> 1750 | Y13: 3500
A14: 417 авто-вышка | B14: 96.5 | C14: =$W$14 -> 1250 | D14: =B14*C14 -> 120625 | F14: =$W$14 -> 1250 | G14: =E14*F14 -> 0 | K14: 417 авто-вышка | L14: 96.5 | M14: =$W$14 -> 1250 | N14: =L14*M14 -> 120625 | P14: =$W$14 -> 1250 | Q14: =O14*P14 -> 0 | S14: =$W$14 -> 1250 | T14: =R14*S14 -> 0 | W14: =X14 -> 1250 | X14: =Y14/2 -> 1250 | Y14: 2500
A15: 434 м/автобус(газель) | C15: =$W$15 -> 500 | D15: =B15*C15 -> 0 | F15: =$W$15 -> 500 | G15: =E15*F15 -> 0 | K15: 434 м/автобус(газель) | M15: =$W$15 -> 500 | N15: =L15*M15 -> 0 | P15: =$W$15 -> 500 | Q15: =O15*P15 -> 0 | S15: =$W$15 -> 500 | T15: =R15*S15 -> 0 | W15: =X15 -> 500 | X15: =Y15/2 -> 500 | Y15: 1000
A16: 498 бур-кран,автовышк | B16: 44 | C16: =$W$16 -> 1750 | D16: =B16*C16 -> 77000 | F16: =$W$16 -> 1750 | G16: =E16*F16 -> 0 | K16: 498 бур-кран,автовышк | L16: 44 | M16: =$W$16 -> 1750 | N16: =L16*M16 -> 77000 | P16: =$W$16 -> 1750 | Q16: =O16*P16 -> 0 | S16: =$W$16 -> 1750 | T16: =R16*S16 -> 0 | W16: =X16 -> 1750 | X16: =Y16/2 -> 1750 | Y16: 3500
A17: 629 урал бур-кран | B17: 25 | C17: =$W$17 -> 2000 | D17: =B17*C17 -> 50000 | F17: =$W$17 -> 2000 | G17: =E17*F17 -> 0 | K17: 629 урал бур-кран | L17: 25 | M17: =$W$17 -> 2000 | N17: =L17*M17 -> 50000 | P17: =$W$17 -> 2000 | Q17: =O17*P17 -> 0 | S17: =$W$17 -> 2000 | T17: =R17*S17 -> 0 | W17: =X17 -> 2000 | X17: =Y17/2 -> 2000 | Y17: 4000
A18: 703 бур-кран с автовышк | C18: =$W$18 -> 2000 | D18: =B18*C18 -> 0 | F18: =$W$18 -> 2000 | G18: =E18*F18 -> 0 | K18: 703 бур-кран с автовышк | M18: =$W$18 -> 2000 | N18: =L18*M18 -> 0 | P18: =$W$18 -> 2000 | Q18: =O18*P18 -> 0 | S18: =$W$18 -> 2000 | T18: =R18*S18 -> 0 | W18: =X18 -> 2000 | X18: =Y18/2 -> 2000 | Y18: 4000
A19: 762 служебная | B19: 139 | C19: =$W$19 -> 500 | D19: =B19*C19 -> 69500 | F19: =$W$19 -> 500 | G19: =E19*F19 -> 0 | K19: 762 служебная | L19: 139 | M19: =$W$19 -> 500 | N19: =L19*M19 -> 69500 | P19: =$W$19 -> 500 | Q19: =O19*P19 -> 0 | S19: =$W$19 -> 500 | T19: =R19*S19 -> 0 | W19: =X19 -> 500 | X19: =Y19/2 -> 500 | Y19: 1000
A20: 816 груз.с краном | B20: 48 | C20: =$W$20 -> 1250 | D20: =B20*C20 -> 60000 | F20: =$W$20 -> 1250 | G20: =E20*F20 -> 0 | K20: 816 груз.с краном | L20: =48-R20 -> 24 | M20: =$W$20 -> 1250 | N20: =L20*M20 -> 30000 | P20: =$W$20 -> 1250 | Q20: =O20*P20 -> 0 | R20: 24 | S20: =$W$20 -> 1250 | T20: =R20*S20 -> 30000 | W20: =X20 -> 1250 | X20: =Y20/2 -> 1250 | Y20: 2500
A21: 887 | B21: 56 | C21: =$W$21 -> 1750 | D21: =B21*C21 -> 98000 | F21: =$W$21 -> 1750 | G21: =E21*F21 -> 0 | K21: 887 | L21: 56 | M21: =$W$21 -> 1750 | N21: =L21*M21 -> 98000 | P21: =$W$21 -> 1750 | Q21: =O21*P21 -> 0 | S21: =$W$21 -> 1750 | T21: =R21*S21 -> 0 | W21: =X21 -> 1750 | X21: =Y21/2 -> 1750 | Y21: 3500
A22: эксковатор KUBOTA KX-021 | B22: 18.5 | C22: =$W$21 -> 1750 | D22: =B22*C22 -> 32375 | F22: =$W$21 -> 1750 | G22: =E22*F22 -> 0 | K22: эксковатор KUBOTA KX-021 | L22: 18.5 | M22: =$W$21 -> 1750 | N22: =L22*M22 -> 32375 | P22: =$W$21 -> 1750 | Q22: =O22*P22 -> 0 | S22: =$W$21 -> 1750 | T22: =R22*S22 -> 0 | W22: =X22 -> 1000 | X22: =Y22/2 -> 1000 | Y22: 2000
A23: ДТ 75 | B23: 10.5 | C23: =$W$23 -> 1750 | D23: =B23*C23 -> 18375 | F23: =$W$23 -> 1750 | G23: =E23*F23 -> 0 | K23: ДТ 75 | L23: 10.5 | M23: =$W$23 -> 1750 | N23: =L23*M23 -> 18375 | P23: =$W$23 -> 1750 | Q23: =O23*P23 -> 0 | S23: =$W$23 -> 1750 | T23: =R23*S23 -> 0 | W23: =X23 -> 1750 | X23: =Y23/2 -> 1750 | Y23: 3500
A24: 295+прицеп | C24: =$W$24 -> 2500 | D24: =B24*C24 -> 0 | F24: =$W$24 -> 2500 | G24: =E24*F24 -> 0 | K24: 295+прицеп | L24: 96 | M24: =$W$24 -> 2500 | N24: =L24*M24 -> 240000 | O24: 12 | P24: =$W$24 -> 2500 | Q24: =O24*P24 -> 30000 | R24: 36 | S24: =$W$24 -> 2500 | T24: =R24*S24 -> 90000 | W24: =X24 -> 2500 | X24: =Y24/2 -> 2500 | Y24: 5000
A25: генератор | B25: 0 | D25: 0 | G25: =E25*F25 -> 0 | K25: генератор | L25: 78.5 | N25: 0 | Q25: =O25*P25 -> 0 | T25: =R25*S25 -> 0
A26: бензопила | B26: 10 | D26: 0 | F26: 100 | G26: =E26*F26 -> 0 | K26: бензопила | L26: 66 | M26: 100 | N26: 0 | P26: 100 | Q26: =O26*P26 -> 0 | T26: =R26*S26 -> 0
A27: теплопушка | B27: 0 | C27: 400 | D27: 0 | F27: 400 | G27: =E27*F27 -> 0 | K27: теплопушка | L27: 51 | M27: 400 | N27: 0 | P27: 400 | Q27: =O27*P27 -> 0 | T27: =R27*S27 -> 0
A28: Итого | B28: =SUM(B5:B27) -> 953.95 | D28: =SUM(D5:D27) -> 1183412.5 | E28: =SUM(E5:E27) -> 8 | G28: =SUM(G5:G27) -> 14000 | K28: Итого ОБЩАЯ | L28: =SUM(L5:L27) -> 1175.45 | N28: =SUM(N5:N27) -> 1330412.5 | O28: =SUM(O5:O27) -> 20 | Q28: =SUM(Q5:Q27) -> 44000 | R28: =SUM(R5:R27) -> 96 | T28: =SUM(T5:T27) -> 183000
K29: ИТОГО ФАКТ | L29: =B28 -> 953.95 | N29: =D28 -> 1183412.5 | O29: =E28 -> 8 | Q29: =G28 -> 14000
A30: ИТОГО | G30: =G28-G29 -> 14000 | K30: ИТОГО РАЗНИЦА | L30: =L28-L29 -> 221.5 | N30: =N28-N29 -> 147000 | O30: =O28-O29 -> 12 | Q30: =Q28-Q29 -> 30000 | R30: =R28-R29 -> 96 | T30: =T28-T29 -> 183000
N33: ='03.26 (изм)'!O35 -> 3609087.5
B34: ЯНВАРЬ | D34: ВАРГА | E34: РАЗНИЦА
A35: Машина | B35: АМУР-ЭП | C35: Леонов | E35: ЭС+
B36: час | C36: цена | D36: сумма | E36: час | F36: цена | G36: сумма
A37: 110 HINO RANGER | B37: 16 | C37: 3500 | D37: =B37*C37 -> 56000 | F37: 3500 | G37: =E37*F37 -> 0
A38: 168 служебная | C38: 1000 | D38: =B38*C38 -> 0 | F38: 1000 | G38: =E38*F38 -> 0
A39: 185 груз.самосвал | B39: 48 | C39: 3500 | D39: =B39*C39 -> 168000 | F39: 3500 | G39: =E39*F39 -> 0
A40: 187 груз.с краном | C40: 3500 | D40: =B40*C40 -> 0 | F40: 3500 | G40: =E40*F40 -> 0
A41: 254 бур-кран+перевоз опор | B41: 103 | C41: 3500 | D41: =B41*C41 -> 360500 | F41: 3500 | G41: =E41*F41 -> 0
A42: 278 2-х кабин.грузовая | C42: 1000 | D42: =B42*C42 -> 0 | F42: 1000 | G42: =E42*F42 -> 0
A43: 365 2-х кабинник | C43: 1000 | D43: =B43*C43 -> 0 | F43: 1000 | G43: =E43*F43 -> 0
...

Sheet 01.26
B1: ЯНВАРЬ | D1: ВАРГА | E1: ФАКТ | L1: ЯНВАРЬ | N1: ВАРГА
A2: Машина | B2: АМУР-ЭП | C2: Леонов | E2: ЭС+ | K2: Машина | L2: АМУР-ЭП | M2: Леонов | O2: ЭС+
B3: час | C3: цена | D3: сумма | E3: час | F3: цена | G3: сумма | L3: час | M3: цена | N3: сумма | O3: час | P3: цена | Q3: сумма
A4: 110 HINO RANGER | B4: 96 | C4: 3500 | D4: =B4*C4 -> 336000 | E4: 8 | F4: 3500 | G4: =E4*F4 -> 28000 | K4: 110 HINO RANGER | L4: 112 | M4: 3500 | N4: =L4*M4 -> 392000 | O4: 8 | P4: 3500 | Q4: =O4*P4 -> 28000
A5: 168 служебная | B5: 143 | C5: 1000 | D5: =B5*C5 -> 143000 | F5: 1000 | G5: =E5*F5 -> 0 | K5: 168 служебная | L5: 143 | M5: 1000 | N5: =L5*M5 -> 143000 | P5: 1000 | Q5: =O5*P5 -> 0
A6: 185 груз.самосвал | B6: 88.45 | C6: 3500 | D6: =B6*C6 -> 309575 | F6: 3500 | G6: =E6*F6 -> 0 | K6: 185 груз.самосвал | L6: 136.45 | M6: 3500 | N6: =L6*M6 -> 477575 | P6: 3500 | Q6: =O6*P6 -> 0
A7: 187 груз.с краном | B7: 112 | C7: 3500 | D7: =B7*C7 -> 392000 | F7: 3500 | G7: =E7*F7 -> 0 | K7: 187 груз.с краном | L7: 112 | M7: 3500 | N7: =L7*M7 -> 392000 | P7: 3500 | Q7: =O7*P7 -> 0
A8: 254 бур-кран+перевоз опор | B8: 27 | C8: 3500 | D8: =B8*C8 -> 94500 | F8: 3500 | G8: =E8*F8 -> 0 | K8: 254 бур-кран+перевоз опор | L8: 130 | M8: 3500 | N8: =L8*M8 -> 455000 | P8: 3500 | Q8: =O8*P8 -> 0
A9: 278 2-х кабин.грузовая | B9: 24 | C9: 1000 | D9: =B9*C9 -> 24000 | F9: 1000 | G9: =E9*F9 -> 0 | K9: 278 2-х кабин.грузовая | L9: 24 | M9: 1000 | N9: =L9*M9 -> 24000 | P9: 1000 | Q9: =O9*P9 -> 0
A10: 365 2-х кабинник | B10: 8 | C10: 1000 | D10: =B10*C10 -> 8000 | F10: 1000 | G10: =E10*F10 -> 0 | K10: 365 2-х кабинник | L10: 8 | M10: 1000 | N10: =L10*M10 -> 8000 | P10: 1000 | Q10: =O10*P10 -> 0
A11: 344 2-х кабинник | B11: 8 | C11: 1000 | D11: =B11*C11 -> 8000 | F11: 1000 | G11: =E11*F11 -> 0 | K11: 344 2-х кабинник | L11: 8 | M11: 1000 | N11: =L11*M11 -> 8000 | P11: 1000 | Q11: =O11*P11 -> 0
A12: 301 бур-кран с автовышк. | C12: 3000 | D12: =B12*C12 -> 0 | F12: 3000 | G12: =E12*F12 -> 0 | K12: 301 бур-кран с автовышк. | M12: 3000 | N12: =L12*M12 -> 0 | P12: 3000 | Q12: =O12*P12 -> 0
A13: 417 авто-вышка | B13: 96.5 | C13: 2500 | D13: =B13*C13 -> 241250 | F13: 2500 | G13: =E13*F13 -> 0 | K13: 417 авто-вышка | L13: 96.5 | M13: 2500 | N13: =L13*M13 -> 241250 | P13: 2500 | Q13: =O13*P13 -> 0
A14: 498 бур-кран,автовышк | B14: 44 | C14: 3500 | D14: =B14*C14 -> 154000 | F14: 3500 | G14: =E14*F14 -> 0 | K14: 498 бур-кран,автовышк | L14: 44 | M14: 3500 | N14: =L14*M14 -> 154000 | P14: 3500 | Q14: =O14*P14 -> 0
A15: 629 урал бур-кран | B15: 25 | C15: 4000 | D15: =B15*C15 -> 100000 | F15: 4000 | G15: =E15*F15 -> 0 | K15: 629 урал бур-кран | L15: 145 | M15: 4000 | N15: =L15*M15 -> 580000 | P15: 4000 | Q15: =O15*P15 -> 0
A16: 703 бур-кран с автовышк | C16: 4000 | D16: =B16*C16 -> 0 | F16: 4000 | G16: =E16*F16 -> 0 | K16: 703 бур-кран с автовышк | M16: 4000 | N16: =L16*M16 -> 0 | P16: 4000 | Q16: =O16*P16 -> 0
A17: 762 служебная | B17: 139 | C17: 1000 | D17: =B17*C17 -> 139000 | F17: 1000 | G17: =E17*F17 -> 0 | K17: 762 служебная | L17: 139 | M17: 1000 | N17: =L17*M17 -> 139000 | P17: 1000 | Q17: =O17*P17 -> 0
A18: 816 груз.с краном | B18: 48 | C18: 2500 | D18: =B18*C18 -> 120000 | F18: 2500 | G18: =E18*F18 -> 0 | K18: 816 груз.с краном | L18: 48 | M18: 2500 | N18: =L18*M18 -> 120000 | P18: 2500 | Q18: =O18*P18 -> 0
A19: 887 | B19: 56 | C19: 3000 | D19: =B19*C19 -> 168000 | F19: 3000 | G19: =E19*F19 -> 0 | K19: 887 | L19: 56 | M19: 3000 | N19: =L19*M19 -> 168000 | P19: 3000 | Q19: =O19*P19 -> 0
A20: эксковатор KUBOTA KX-021 | B20: 18.5 | C20: 2000 | D20: =B20*C20 -> 37000 | F20: 2000 | G20: =E20*F20 -> 0 | K20: эксковатор KUBOTA KX-021 | L20: 61.5 | M20: 2000 | N20: =L20*M20 -> 123000 | P20: 2000 | Q20: =O20*P20 -> 0
A21: ДТ 75 | B21: 10.5 | C21: 3500 | D21: =B21*C21 -> 36750 | F21: 3500 | G21: =E21*F21 -> 0 | K21: ДТ 75 | L21: 10.5 | M21: 3500 | N21: =L21*M21 -> 36750 | P21: 3500 | Q21: =O21*P21 -> 0
A22: генератор | B22: 0 | C22: 600 | D22: 0 | E22: 27 | F22: 600 | G22: =E22*F22 -> 16200 | K22: генератор | L22: 78.5 | M22: 600 | N22: 0 | P22: 600 | Q22: =O22*P22 -> 0
A23: бензопила | B23: 10 | C23: 100 | D23: 0 | F23: 100 | G23: =E23*F23 -> 0 | K23: бензопила | L23: 66 | M23: 100 | N23: 0 | P23: 100 | Q23: =O23*P23 -> 0
A24: теплопушка | B24: 0 | C24: 400 | D24: 0 | F24: 400 | G24: =E24*F24 -> 0 | K24: теплопушка | L24: 51 | M24: 400 | N24: 0 | P24: 400 | Q24: =O24*P24 -> 0
A25: Итого | B25: =SUM(B4:B24) -> 953.95 | D25: =SUM(D4:D24) -> 2311075 | E25: =SUM(E4:E24) -> 35 | G25: =SUM(G4:G24) -> 44200 | K25: Итого ОБЩАЯ | L25: =SUM(L4:L24) -> 1469.45 | N25: =SUM(N4:N24) -> 3461575 | O25: =SUM(O4:O24) -> 8 | Q25: =SUM(Q4:Q24) -> 28000
K26: ИТОГО ФАКТ | L26: 943.95 | N26: 2311075 | O26: 8 | Q26: 28000
A27: ИТОГО | G27: =G25-G26 -> 44200 | K27: ИТОГО РАЗНИЦА | L27: =L25-L26 -> 525.5 | N27: =N25-N26 -> 1150500 | O27: =O25-O26 -> 0 | Q27: =Q25-Q26 -> 0
B31: ЯНВАРЬ | D31: ВАРГА | E31: РАЗНИЦА
A32: Машина | B32: АМУР-ЭП | C32: Леонов | E32: ЭС+
B33: час | C33: цена | D33: сумма | E33: час | F33: цена | G33: сумма
A34: 110 HINO RANGER | B34: 16 | C34: 3500 | D34: =B34*C34 -> 56000 | F34: 3500 | G34: =E34*F34 -> 0
A35: 168 служебная | C35: 1000 | D35: =B35*C35 -> 0 | F35: 1000 | G35: =E35*F35 -> 0
A36: 185 груз.самосвал | B36: 48 | C36: 3500 | D36: =B36*C36 -> 168000 | F36: 3500 | G36: =E36*F36 -> 0
A37: 187 груз.с краном | C37: 3500 | D37: =B37*C37 -> 0 | F37: 3500 | G37: =E37*F37 -> 0
A38: 254 бур-кран+перевоз опор | B38: 103 | C38: 3500 | D38: =B38*C38 -> 360500 | F38: 3500 | G38: =E38*F38 -> 0
A39: 278 2-х кабин.грузовая | C39: 1000 | D39: =B39*C39 -> 0 | F39: 1000 | G39: =E39*F39 -> 0
A40: 365 2-х кабинник | C40: 1000 | D40: =B40*C40 -> 0 | F40: 1000 | G40: =E40*F40 -> 0
A41: 344 2-х кабинник | C41: 1000 | D41: =B41*C41 -> 0 | F41: 1000 | G41: =E41*F41 -> 0
A42: 301 бур-кран с автовышк. | C42: 3000 | D42: =B42*C42 -> 0 | F42: 3000 | G42: =E42*F42 -> 0
A43: 417 авто-вышка | C43: 2500 | D43: =B43*C43 -> 0 | F43: 2500 | G43: =E43*F43 -> 0
...

Sheet 02.26 (изм)
C2: ФЕВРАЛЬ | E2: ВАРГА | F2: ФАКТ | K2: ФЕВРАЛЬ | M2: ВАРГА
B3: Машина | C3: АМУР-ЭП | D3: Леонов | F3: ЭС+ | J3: Машина | K3: АМУР-ЭП | L3: Леонов | N3: ЭС+ | Q3: АМУР-ЭП | R3: Мурзин
C4: час | D4: цена | E4: сумма | F4: час | G4: цена | H4: сумма | K4: час | L4: цена | M4: сумма | N4: час | O4: цена | P4: сумма | Q4: час | R4: цена | S4: сумма
A5: 271 | B5: 110 буровая | C5: 48 | D5: =$V$5 -> 1750 | E5: =C5*D5 -> 84000 | F5: 81 | G5: =$V$5 -> 1750 | H5: =F5*G5 -> 141750 | J5: 110 HINO RANGER | K5: 48 | L5: =$V$5 -> 1750 | M5: =K5*L5 -> 84000 | N5: 33 | O5: =$V$5 -> 1750 | P5: =N5*O5 -> 57750 | Q5: 24 | R5: =$V$5 -> 1750 | S5: =Q5*R5 -> 42000 | V5: =W5 -> 1750 | W5: =X5/2 -> 1750 | X5: 3500
B6: 168 служебная | C6: 204 | D6: =$V$6 -> 500 | E6: =C6*D6 -> 102000 | G6: =$V$6 -> 500 | H6: =F6*G6 -> 0 | J6: 168 служебная | K6: 204 | L6: =$V$6 -> 500 | M6: =K6*L6 -> 102000 | O6: =$V$6 -> 500 | P6: =N6*O6 -> 0 | R6: =$V$6 -> 500 | S6: =Q6*R6 -> 0 | V6: =W6 -> 500 | W6: =X6/2 -> 500 | X6: 1000
B7: 185 груз.самосвал | C7: 24 | D7: =$V$7 -> 1750 | E7: =C7*D7 -> 42000 | G7: =$V$7 -> 1750 | H7: =F7*G7 -> 0 | J7: 185 груз.самосвал | K7: 24 | L7: =$V$7 -> 1750 | M7: =K7*L7 -> 42000 | O7: =$V$7 -> 1750 | P7: =N7*O7 -> 0 | R7: =$V$7 -> 1750 | S7: =Q7*R7 -> 0 | V7: =W7 -> 1750 | W7: =X7/2 -> 1750 | X7: 3500
A8: нет | B8: 187 груз.с краном | C8: 76 | D8: =$V$8 -> 1750 | E8: =C8*D8 -> 133000 | G8: =$V$8 -> 1750 | H8: =F8*G8 -> 0 | J8: 187 груз.с краном | K8: =76-Q8 -> 52 | L8: =$V$8 -> 1750 | M8: =K8*L8 -> 91000 | O8: =$V$8 -> 1750 | P8: =N8*O8 -> 0 | Q8: 24 | R8: =$V$8 -> 1750 | S8: =Q8*R8 -> 42000 | V8: =W8 -> 1750 | W8: =X8/2 -> 1750 | X8: 3500
B9: 254 бур-кран+перевоз опор | C9: 146 | D9: =$V$9 -> 1750 | E9: =C9*D9 -> 255500 | G9: =$V$9 -> 1750 | H9: =F9*G9 -> 0 | J9: 254 бур-кран+перевоз опор | K9: 146 | L9: =$V$9 -> 1750 | M9: =K9*L9 -> 255500 | O9: =$V$9 -> 1750 | P9: =N9*O9 -> 0 | R9: =$V$9 -> 1750 | S9: =Q9*R9 -> 0 | V9: =W9 -> 1750 | W9: =X9/2 -> 1750 | X9: 3500
B10: 278 2-х каб.груз.-бортовой | C10: 94.5 | D10: =$V$10 -> 500 | E10: =C10*D10 -> 47250 | G10: =$V$10 -> 500 | H10: =F10*G10 -> 0 | J10: 278 2-х кабин.грузовая | K10: 94.5 | L10: =$V$10 -> 500 | M10: =K10*L10 -> 47250 | O10: =$V$10 -> 500 | P10: =N10*O10 -> 0 | R10: =$V$10 -> 500 | S10: =Q10*R10 -> 0 | V10: =W10 -> 500 | W10: =X10/2 -> 500 | X10: 1000
B11: 365 2-х кабинник | D11: =$V$11 -> 500 | E11: =C11*D11 -> 0 | G11: =$V$11 -> 500 | H11: =F11*G11 -> 0 | J11: 365 2-х кабинник | L11: =$V$11 -> 500 | M11: =K11*L11 -> 0 | O11: =$V$11 -> 500 | P11: =N11*O11 -> 0 | R11: =$V$11 -> 500 | S11: =Q11*R11 -> 0 | V11: =W11 -> 500 | W11: =X11/2 -> 500 | X11: 1000
B12: 344 2-х каб.груз.-бортовой | D12: =$V$12 -> 500 | E12: =C12*D12 -> 0 | G12: =$V$12 -> 500 | H12: =F12*G12 -> 0 | J12: 344 2-х кабинник | L12: =$V$12 -> 500 | M12: =K12*L12 -> 0 | O12: =$V$12 -> 500 | P12: =N12*O12 -> 0 | R12: =$V$12 -> 500 | S12: =Q12*R12 -> 0 | V12: =W12 -> 500 | W12: =X12/2 -> 500 | X12: 1000
B13: 301 бур-кран с автовышк. | D13: =$V$13 -> 1750 | E13: =C13*D13 -> 0 | G13: =$V$13 -> 1750 | H13: =F13*G13 -> 0 | J13: 301 бур-кран с автовышк. | L13: =$V$13 -> 1750 | M13: =K13*L13 -> 0 | O13: =$V$13 -> 1750 | P13: =N13*O13 -> 0 | R13: =$V$13 -> 1750 | S13: =Q13*R13 -> 0 | V13: =W13 -> 1750 | W13: =X13/2 -> 1750 | X13: 3500
B14: 417 авто-вышка | C14: 64 | D14: =$V$14 -> 1250 | E14: =C14*D14 -> 80000 | G14: =$V$14 -> 1250 | H14: =F14*G14 -> 0 | J14: 417 авто-вышка | K14: 64 | L14: =$V$14 -> 1250 | M14: =K14*L14 -> 80000 | O14: =$V$14 -> 1250 | P14: =N14*O14 -> 0 | R14: =$V$14 -> 1250 | S14: =Q14*R14 -> 0 | V14: =W14 -> 1250 | W14: =X14/2 -> 1250 | X14: 2500
B15: 434 м/автобус(газель) | D15: =$V$15 -> 500 | E15: =C15*D15 -> 0 | G15: =$V$15 -> 500 | H15: =F15*G15 -> 0 | J15: 434 м/автобус(газель) | L15: =$V$15 -> 500 | M15: =K15*L15 -> 0 | O15: =$V$15 -> 500 | P15: =N15*O15 -> 0 | R15: =$V$15 -> 500 | S15: =Q15*R15 -> 0 | V15: =W15 -> 500 | W15: =X15/2 -> 500 | X15: 1000
A16: нет | B16: 498 бур-кран,автовышк | C16: 20 | D16: =$V$16 -> 1750 | E16: =C16*D16 -> 35000 | G16: =$V$16 -> 1750 | H16: =F16*G16 -> 0 | J16: 498 бур-кран,автовышк | K16: 20 | L16: =$V$16 -> 1750 | M16: =K16*L16 -> 35000 | O16: =$V$16 -> 1750 | P16: =N16*O16 -> 0 | R16: =$V$16 -> 1750 | S16: =Q16*R16 -> 0 | V16: =W16 -> 1750 | W16: =X16/2 -> 1750 | X16: 3500
B17: 629 урал бур-кран | C17: 8 | D17: =$V$17 -> 2000 | E17: =C17*D17 -> 16000 | G17: =$V$17 -> 2000 | H17: =F17*G17 -> 0 | J17: 629 урал бур-кран | K17: 8 | L17: =$V$17 -> 2000 | M17: =K17*L17 -> 16000 | O17: =$V$17 -> 2000 | P17: =N17*O17 -> 0 | R17: =$V$17 -> 2000 | S17: =Q17*R17 -> 0 | V17: =W17 -> 2000 | W17: =X17/2 -> 2000 | X17: 4000
B18: 703 бур-кран с автовышк | D18: =$V$18 -> 2000 | E18: =C18*D18 -> 0 | G18: =$V$18 -> 2000 | H18: =F18*G18 -> 0 | J18: 703 бур-кран с автовышк | L18: =$V$18 -> 2000 | M18: =K18*L18 -> 0 | O18: =$V$18 -> 2000 | P18: =N18*O18 -> 0 | R18: =$V$18 -> 2000 | S18: =Q18*R18 -> 0 | V18: =W18 -> 2000 | W18: =X18/2 -> 2000 | X18: 4000
B19: 762 служеб.м/автобус | C19: 81 | D19: =$V$19 -> 500 | E19: =C19*D19 -> 40500 | G19: =$V$19 -> 500 | H19: =F19*G19 -> 0 | J19: 762 служебная | K19: 81 | L19: =$V$19 -> 500 | M19: =K19*L19 -> 40500 | O19: =$V$19 -> 500 | P19: =N19*O19 -> 0 | R19: =$V$19 -> 500 | S19: =Q19*R19 -> 0 | V19: =W19 -> 500 | W19: =X19/2 -> 500 | X19: 1000
B20: 816 груз.-борт.с краном | C20: 120 | D20: =$V$20 -> 1250 | E20: =C20*D20 -> 150000 | G20: =$V$20 -> 1250 | H20: =F20*G20 -> 0 | J20: 816 груз.с краном | K20: =120-Q20 -> 84 | L20: =$V$20 -> 1250 | M20: =K20*L20 -> 105000 | O20: =$V$20 -> 1250 | P20: =N20*O20 -> 0 | Q20: 36 | R20: =$V$20 -> 1250 | S20: =Q20*R20 -> 45000 | V20: =W20 -> 1250 | W20: =X20/2 -> 1250 | X20: 2500
A21: нет | B21: 887 бур-кран с автовышк | C21: 24 | D21: =$V$21 -> 1750 | E21: =C21*D21 -> 42000 | G21: =$V$21 -> 1750 | H21: =F21*G21 -> 0 | J21: 887 | K21: 24 | L21: =$V$21 -> 1750 | M21: =K21*L21 -> 42000 | O21: =$V$21 -> 1750 | P21: =N21*O21 -> 0 | R21: =$V$21 -> 1750 | S21: =Q21*R21 -> 0 | V21: =W21 -> 1750 | W21: =X21/2 -> 1750 | X21: 3500
B22: эксковатор KUBOTA KX-021 | C22: 16.6 | D22: =$V$21 -> 1750 | E22: =C22*D22 -> 29050 | G22: =$V$21 -> 1750 | H22: =F22*G22 -> 0 | J22: эксковатор KUBOTA KX-021 | K22: 16.6 | L22: =$V$21 -> 1750 | M22: =K22*L22 -> 29050 | O22: =$V$21 -> 1750 | P22: =N22*O22 -> 0 | R22: =$V$21 -> 1750 | S22: =Q22*R22 -> 0 | V22: =W22 -> 1000 | W22: =X22/2 -> 1000 | X22: 2000
B23: ДТ 42 | C23: 11 | D23: =$V$23 -> 1750 | E23: =C23*D23 -> 19250 | F23: 5.4 | G23: =$V$23 -> 1750 | H23: =F23*G23 -> 9450 | J23: ДТ 75 | K23: 11 | L23: =$V$23 -> 1750 | M23: =K23*L23 -> 19250 | N23: 5 | O23: =$V$23 -> 1750 | P23: =N23*O23 -> 8750 | R23: =$V$23 -> 1750 | S23: =Q23*R23 -> 0 | V23: =W23 -> 1750 | W23: =X23/2 -> 1750 | X23: 3500
B24: 295+прицеп | D24: =$V$24 -> 2500 | E24: =C24*D24 -> 0 | G24: =$V$24 -> 2500 | H24: =F24*G24 -> 0 | J24: 295+прицеп | K24: 88 | L24: =$V$24 -> 2500 | M24: =K24*L24 -> 220000 | N24: 18 | O24: =$V$24 -> 2500 | P24: =N24*O24 -> 45000 | Q24: =8+6+4+4+6+6 -> 34 | R24: =$V$24 -> 2500 | S24: =Q24*R24 -> 85000 | V24: =W24 -> 2500 | W24: =X24/2 -> 2500 | X24: 5000
B25: генератор | E25: =C25*D25 -> 0 | H25: =F25*G25 -> 0 | J25: генератор | M25: =K25*L25 -> 0 | P25: =N25*O25 -> 0 | S25: =Q25*R25 -> 0
B26: бензопила | E26: =C26*D26 -> 0 | H26: =F26*G26 -> 0 | J26: бензопила | M26: =K26*L26 -> 0 | P26: =N26*O26 -> 0 | S26: =Q26*R26 -> 0
B27: теплопушка | E27: =C27*D27 -> 0 | H27: =F27*G27 -> 0 | J27: теплопушка | M27: =K27*L27 -> 0 | P27: =N27*O27 -> 0 | S27: =Q27*R27 -> 0
B28: Итого | C28: =SUM(C5:C27) -> 937.1 | E28: =SUM(E5:E27) -> 1075550 | F28: =SUM(F5:F27) -> 86.4 | H28: =SUM(H5:H27) -> 151200 | J28: Итого ОБЩАЯ | K28: =SUM(K5:K27) -> 965.1 | M28: =SUM(M5:M27) -> 1208550 | N28: =SUM(N5:N27) -> 56 | P28: =SUM(P5:P27) -> 111500 | Q28: =SUM(Q5:Q27) -> 118 | S28: =SUM(S5:S27) -> 214000
J29: ИТОГО ФАКТ | K29: =C28 -> 937.1 | M29: =E28 -> 1075550 | N29: =F28 -> 86.4 | P29: =H28 -> 151200
B30: ИТОГО | H30: =H28-H29 -> 151200 | J30: ИТОГО РАЗНИЦА | K30: =K28-K29 -> 28 | M30: =M28-M29 -> 133000 | N30: =N28-N29 -> -30.4 | P30: =P28-P29 -> -39700 | Q30: =Q28-Q29 -> 118 | S30: =S28-S29 -> 214000
C32: ФЕВРАЛЬ | E32: ВАРГА | F32: РАЗНИЦА
B33: Машина | C33: АМУР-ЭП | D33: Леонов | F33: ЭС+
C34: час | D34: цена | E34: сумма | F34: час | G34: цена | H34: сумма
B35: 110 HINO RANGER | C35: =K5-C5 -> 0 | D35: 3500 | E35: =C35*D35 -> 0 | G35: 3500 | H35: =F35*G35 -> 0 | M35: ='03.26 (изм)'!O35 -> 3609087.5 | Q35: ='03.26 (изм)'!R35 -> 545000 | S35: ='03.26 (изм)'!U35 -> 629750
B36: 168 служебная | C36: =K6-C6 -> 0 | D36: 1000 | E36: =C36*D36 -> 0 | G36: 1000 | H36: =F36*G36 -> 0
B37: 185 груз.самосвал | C37: =K7-C7 -> 0 | D37: 3500 | E37: =C37*D37 -> 0 | G37: 3500 | H37: =F37*G37 -> 0
B38: 187 груз.с краном | C38: =K8-C8 -> -24 | D38: 3500 | E38: =C38*D38 -> -84000 | G38: 3500 | H38: =F38*G38 -> 0
B39: 254 бур-кран+перевоз опор | C39: =K9-C9 -> 0 | D39: 3500 | E39: =C39*D39 -> 0 | G39: 3500 | H39: =F39*G39 -> 0
B40: 278 2-х кабин.грузовая | C40: =K10-C10 -> 0 | D40: 1000 | E40: =C40*D40 -> 0 | G40: 1000 | H40: =F40*G40 -> 0
B41: 365 2-х кабинник | C41: =K11-C11 -> 0 | D41: 1000 | E41: =C41*D41 -> 0 | G41: 1000 | H41: =F41*G41 -> 0
B42: 344 2-х кабинник | C42: =K12-C12 -> 0 | D42: 1000 | E42: =C42*D42 -> 0 | G42: 1000 | H42: =F42*G42 -> 0
...

Sheet 02.26
C1: ФЕВРАЛЬ | E1: ВАРГА | F1: ФАКТ | K1: ФЕВРАЛЬ | M1: ВАРГА
B2: Машина | C2: АМУР-ЭП | D2: Леонов | F2: ЭС+ | J2: Машина | K2: АМУР-ЭП | L2: Леонов | N2: ЭС+
C3: час | D3: цена | E3: сумма | F3: час | G3: цена | H3: сумма | K3: час | L3: цена | M3: сумма | N3: час | O3: цена | P3: сумма
A4: 271 | B4: 110 буровая | C4: 48 | D4: 3500 | E4: =C4*D4 -> 168000 | F4: 81 | G4: 3500 | H4: =F4*G4 -> 283500 | J4: 110 HINO RANGER | K4: 112 | L4: 3500 | M4: =K4*L4 -> 392000 | N4: 81 | O4: 3500 | P4: =N4*O4 -> 283500
B5: 168 служебная | C5: 204 | D5: 1000 | E5: =C5*D5 -> 204000 | G5: 1000 | H5: =F5*G5 -> 0 | J5: 168 служебная | K5: 228 | L5: 1000 | M5: =K5*L5 -> 228000 | O5: 1000 | P5: =N5*O5 -> 0
B6: 185 груз.самосвал | C6: 24 | D6: 3500 | E6: =C6*D6 -> 84000 | G6: 3500 | H6: =F6*G6 -> 0 | J6: 185 груз.самосвал | K6: 144 | L6: 3500 | M6: =K6*L6 -> 504000 | O6: 3500 | P6: =N6*O6 -> 0
A7: нет | B7: 187 груз.с краном | C7: 76 | D7: 3500 | E7: =C7*D7 -> 266000 | G7: 3500 | H7: =F7*G7 -> 0 | J7: 187 груз.с краном | K7: 76 | L7: 3500 | M7: =K7*L7 -> 266000 | O7: 3500 | P7: =N7*O7 -> 0
B8: 254 бур-кран+перевоз опор | C8: 146 | D8: 3500 | E8: =C8*D8 -> 511000 | G8: 3500 | H8: =F8*G8 -> 0 | J8: 254 бур-кран+перевоз опор | K8: 146 | L8: 3500 | M8: =K8*L8 -> 511000 | O8: 3500 | P8: =N8*O8 -> 0
B9: 278 2-х каб.груз.-бортовой | C9: 94.5 | D9: 1000 | E9: =C9*D9 -> 94500 | G9: 1000 | H9: =F9*G9 -> 0 | J9: 278 2-х кабин.грузовая | K9: 155 | L9: 1000 | M9: =K9*L9 -> 155000 | O9: 1000 | P9: =N9*O9 -> 0
B10: 365 2-х кабинник | D10: 1000 | E10: =C10*D10 -> 0 | G10: 1000 | H10: =F10*G10 -> 0 | J10: 365 2-х кабинник | L10: 1000 | M10: =K10*L10 -> 0 | O10: 1000 | P10: =N10*O10 -> 0
B11: 344 2-х каб.груз.-бортовой | D11: 1000 | E11: =C11*D11 -> 0 | G11: 1000 | H11: =F11*G11 -> 0 | J11: 344 2-х кабинник | L11: 1000 | M11: =K11*L11 -> 0 | O11: 1000 | P11: =N11*O11 -> 0
B12: 301 бур-кран с автовышк. | D12: 3000 | E12: =C12*D12 -> 0 | G12: 3000 | H12: =F12*G12 -> 0 | J12: 301 бур-кран с автовышк. | L12: 3000 | M12: =K12*L12 -> 0 | O12: 3000 | P12: =N12*O12 -> 0
B13: 417 авто-вышка | C13: 64 | D13: 2500 | E13: =C13*D13 -> 160000 | G13: 2500 | H13: =F13*G13 -> 0 | J13: 417 авто-вышка | K13: 144 | L13: 2500 | M13: =K13*L13 -> 360000 | O13: 2500 | P13: =N13*O13 -> 0
A14: нет | B14: 498 бур-кран,автовышк | C14: 20 | D14: 3500 | E14: =C14*D14 -> 70000 | G14: 3500 | H14: =F14*G14 -> 0 | J14: 498 бур-кран,автовышк | K14: 20 | L14: 3500 | M14: =K14*L14 -> 70000 | O14: 3500 | P14: =N14*O14 -> 0
B15: 629 урал бур-кран | C15: 8 | D15: 4000 | E15: =C15*D15 -> 32000 | G15: 4000 | H15: =F15*G15 -> 0 | J15: 629 урал бур-кран | K15: 8 | L15: 4000 | M15: =K15*L15 -> 32000 | O15: 4000 | P15: =N15*O15 -> 0
B16: 703 бур-кран с автовышк | D16: 4000 | E16: =C16*D16 -> 0 | G16: 4000 | H16: =F16*G16 -> 0 | J16: 703 бур-кран с автовышк | L16: 4000 | M16: =K16*L16 -> 0 | O16: 4000 | P16: =N16*O16 -> 0
B17: 762 служеб.м/автобус | C17: 81 | D17: 1000 | E17: =C17*D17 -> 81000 | G17: 1000 | H17: =F17*G17 -> 0 | J17: 762 служебная | K17: 137 | L17: 1000 | M17: =K17*L17 -> 137000 | O17: 1000 | P17: =N17*O17 -> 0
B18: 816 груз.-борт.с краном | C18: 120 | D18: 2500 | E18: =C18*D18 -> 300000 | G18: 2500 | H18: =F18*G18 -> 0 | J18: 816 груз.с краном | K18: 144 | L18: 2500 | M18: =K18*L18 -> 360000 | O18: 2500 | P18: =N18*O18 -> 0
A19: нет | B19: 887 бур-кран с автовышк | C19: 24 | D19: 3000 | E19: =C19*D19 -> 72000 | G19: 3000 | H19: =F19*G19 -> 0 | J19: 887 | K19: 80 | L19: 3000 | M19: =K19*L19 -> 240000 | O19: 3000 | P19: =N19*O19 -> 0
B20: эксковатор KUBOTA KX-021 | C20: 16.6 | D20: 2000 | E20: =C20*D20 -> 33200 | G20: 2000 | H20: =F20*G20 -> 0 | J20: эксковатор KUBOTA KX-021 | K20: 44.6 | L20: 2000 | M20: =K20*L20 -> 89200 | O20: 2000 | P20: =N20*O20 -> 0
B21: ДТ 42 | C21: 11 | D21: 3500 | E21: =C21*D21 -> 38500 | F21: 5.4 | G21: 3500 | H21: =F21*G21 -> 18900 | J21: ДТ 75 | K21: 11 | L21: 3500 | M21: =K21*L21 -> 38500 | N21: 5.4 | O21: 3500 | P21: =N21*O21 -> 18900
B22: генератор | E22: =C22*D22 -> 0 | H22: =F22*G22 -> 0 | J22: генератор | M22: =K22*L22 -> 0 | P22: =N22*O22 -> 0
B23: бензопила | E23: =C23*D23 -> 0 | H23: =F23*G23 -> 0 | J23: бензопила | M23: =K23*L23 -> 0 | P23: =N23*O23 -> 0
B24: теплопушка | E24: =C24*D24 -> 0 | H24: =F24*G24 -> 0 | J24: теплопушка | M24: =K24*L24 -> 0 | P24: =N24*O24 -> 0
B25: Итого | C25: =SUM(C4:C24) -> 937.1 | E25: =SUM(E4:E24) -> 2114200 | F25: =SUM(F4:F24) -> 86.4 | H25: =SUM(H4:H24) -> 302400 | J25: Итого ОБЩАЯ | K25: =SUM(K4:K24) -> 1449.6 | M25: =SUM(M4:M24) -> 3382700 | N25: =SUM(N4:N24) -> 86.4 | P25: =SUM(P4:P24) -> 302400
J26: ИТОГО ФАКТ | K26: 917.1 | M26: 2114200 | N26: 86.4 | P26: 302400
B27: ИТОГО | H27: =H25-H26 -> 302400 | J27: ИТОГО РАЗНИЦА | K27: =K25-K26 -> 532.5 | M27: =M25-M26 -> 1268500 | N27: =N25-N26 -> 0 | P27: =P25-P26 -> 0
C29: ФЕВРАЛЬ | E29: ВАРГА | F29: РАЗНИЦА
B30: Машина | C30: АМУР-ЭП | D30: Леонов | F30: ЭС+
C31: час | D31: цена | E31: сумма | F31: час | G31: цена | H31: сумма
B32: 110 HINO RANGER | C32: =K4-C4 -> 64 | D32: 3500 | E32: =C32*D32 -> 224000 | G32: 3500 | H32: =F32*G32 -> 0
B33: 168 служебная | C33: =K5-C5 -> 24 | D33: 1000 | E33: =C33*D33 -> 24000 | G33: 1000 | H33: =F33*G33 -> 0
B34: 185 груз.самосвал | C34: =K6-C6 -> 120 | D34: 3500 | E34: =C34*D34 -> 420000 | G34: 3500 | H34: =F34*G34 -> 0
B35: 187 груз.с краном | C35: =K7-C7 -> 0 | D35: 3500 | E35: =C35*D35 -> 0 | G35: 3500 | H35: =F35*G35 -> 0
B36: 254 бур-кран+перевоз опор | C36: =K8-C8 -> 0 | D36: 3500 | E36: =C36*D36 -> 0 | G36: 3500 | H36: =F36*G36 -> 0
B37: 278 2-х кабин.грузовая | C37: =K9-C9 -> 60.5 | D37: 1000 | E37: =C37*D37 -> 60500 | G37: 1000 | H37: =F37*G37 -> 0
B38: 365 2-х кабинник | C38: =K10-C10 -> 0 | D38: 1000 | E38: =C38*D38 -> 0 | G38: 1000 | H38: =F38*G38 -> 0
B39: 344 2-х кабинник | C39: =K11-C11 -> 0 | D39: 1000 | E39: =C39*D39 -> 0 | G39: 1000 | H39: =F39*G39 -> 0
B40: 301 бур-кран с автовышк. | C40: =K12-C12 -> 0 | D40: 3000 | E40: =C40*D40 -> 0 | G40: 3000 | H40: =F40*G40 -> 0
B41: 417 авто-вышка | C41: =K13-C13 -> 80 | D41: 2500 | E41: =C41*D41 -> 200000 | G41: 2500 | H41: =F41*G41 -> 0
...

Sheet 03.26 (изм)
C2: МАРТ | E2: ВАРГА | F2: ФАКТ | M2: МАРТ | O2: ВАРГА
B3: Машина | C3: АМУР-ЭП | D3: Леонов | F3: ЭС+ | L3: Машина | M3: АМУР-ЭП | N3: Леонов | P3: ЭС+ | S3: АМУР-ЭП | T3: Мурзин
C4: час | D4: цена | E4: сумма | F4: час | G4: цена | H4: сумма | M4: час | N4: цена | O4: сумма | P4: час | Q4: цена | R4: сумма | S4: час | T4: цена | U4: сумма
A5: 271 | B5: 110 буровая | D5: =$X$5 -> 1750 | E5: =C5*D5 -> 0 | F5: 152 | G5: =$X$5 -> 1750 | H5: =F5*G5 -> 266000 | K5: 271 | L5: 110 буровая | N5: =$X$5 -> 1750 | O5: =M5*N5 -> 0 | P5: 14 | Q5: =$X$5 -> 1750 | R5: =P5*Q5 -> 24500 | S5: 40 | T5: =$X$5 -> 1750 | U5: =S5*T5 -> 70000 | X5: =Y5 -> 1750 | Y5: =Z5/2 -> 1750 | Z5: 3500
B6: 168 служебная | C6: 180 | D6: =$X$6 -> 500 | E6: =C6*D6 -> 90000 | G6: =$X$6 -> 500 | H6: =F6*G6 -> 0 | L6: 168 служебная | M6: 180 | N6: =$X$6 -> 500 | O6: =M6*N6 -> 90000 | Q6: =$X$6 -> 500 | R6: =P6*Q6 -> 0 | T6: =$X$6 -> 500 | U6: =S6*T6 -> 0 | X6: =Y6 -> 500 | Y6: =Z6/2 -> 500 | Z6: 1000
B7: 185 груз.самосвал | C7: 8 | D7: =$X$7 -> 1750 | E7: =C7*D7 -> 14000 | F7: 16 | G7: =$X$7 -> 1750 | H7: =F7*G7 -> 28000 | L7: 185 груз.самосвал | M7: 0 | N7: =$X$7 -> 1750 | O7: =M7*N7 -> 0 | P7: 16 | Q7: =$X$7 -> 1750 | R7: =P7*Q7 -> 28000 | S7: 8 | T7: =$X$7 -> 1750 | U7: =S7*T7 -> 14000 | X7: =Y7 -> 1750 | Y7: =Z7/2 -> 1750 | Z7: 3500
A8: нет | B8: 187 груз.с краном | C8: 57 | D8: =$X$8 -> 1750 | E8: =C8*D8 -> 99750 | F8: 16 | G8: =$X$8 -> 1750 | H8: =F8*G8 -> 28000 | K8: нет | L8: 187 груз.с краном | M8: =57-S8 -> 37 | N8: =$X$8 -> 1750 | O8: =M8*N8 -> 64750 | P8: 16 | Q8: =$X$8 -> 1750 | R8: =P8*Q8 -> 28000 | S8: 20 | T8: =$X$8 -> 1750 | U8: =S8*T8 -> 35000 | X8: =Y8 -> 1750 | Y8: =Z8/2 -> 1750 | Z8: 3500
B9: 254 бур-кран+перевоз опор | C9: 35 | D9: =$X$9 -> 1750 | E9: =C9*D9 -> 61250 | G9: =$X$9 -> 1750 | H9: =F9*G9 -> 0 | L9: 254 бур-кран+перевоз опор | M9: 35 | N9: =$X$9 -> 1750 | O9: =M9*N9 -> 61250 | Q9: =$X$9 -> 1750 | R9: =P9*Q9 -> 0 | T9: =$X$9 -> 1750 | U9: =S9*T9 -> 0 | X9: =Y9 -> 1750 | Y9: =Z9/2 -> 1750 | Z9: 3500
B10: 278 2-х каб.груз.-бортовой | C10: 120 | D10: =$X$10 -> 500 | E10: =C10*D10 -> 60000 | F10: 8 | G10: =$X$10 -> 500 | H10: =F10*G10 -> 4000 | L10: 278 2-х каб.груз.-бортовой | M10: 120 | N10: =$X$10 -> 500 | O10: =M10*N10 -> 60000 | P10: 8 | Q10: =$X$10 -> 500 | R10: =P10*Q10 -> 4000 | T10: =$X$10 -> 500 | U10: =S10*T10 -> 0 | X10: =Y10 -> 500 | Y10: =Z10/2 -> 500 | Z10: 1000
B11: 365 2-х кабинник | D11: =$X$11 -> 500 | E11: =C11*D11 -> 0 | G11: =$X$11 -> 500 | H11: =F11*G11 -> 0 | L11: 365 2-х кабинник | N11: =$X$11 -> 500 | O11: =M11*N11 -> 0 | Q11: =$X$11 -> 500 | R11: =P11*Q11 -> 0 | T11: =$X$11 -> 500 | U11: =S11*T11 -> 0 | X11: =Y11 -> 500 | Y11: =Z11/2 -> 500 | Z11: 1000
B12: 344 2-х каб.груз.-бортовой | D12: =$X$12 -> 500 | E12: =C12*D12 -> 0 | G12: =$X$12 -> 500 | H12: =F12*G12 -> 0 | L12: 344 2-х каб.груз.-бортовой | N12: =$X$12 -> 500 | O12: =M12*N12 -> 0 | Q12: =$X$12 -> 500 | R12: =P12*Q12 -> 0 | T12: =$X$12 -> 500 | U12: =S12*T12 -> 0 | X12: =Y12 -> 500 | Y12: =Z12/2 -> 500 | Z12: 1000
B13: 301+498 бур-кран с автовышк. | C13: 48 | D13: =$X$13 -> 1750 | E13: =C13*D13 -> 84000 | G13: =$X$13 -> 1750 | H13: =F13*G13 -> 0 | I13: 3000 было | L13: 301+498 бур-кран с автовышк. | M13: 48 | N13: =$X$13 -> 1750 | O13: =M13*N13 -> 84000 | Q13: =$X$13 -> 1750 | R13: =P13*Q13 -> 0 | T13: =$X$13 -> 1750 | U13: =S13*T13 -> 0 | X13: =Y13 -> 1750 | Y13: =Z13/2 -> 1750 | Z13: 3500
B14: 417 авто-вышка | C14: 24 | D14: =$X$14 -> 1250 | E14: =C14*D14 -> 30000 | F14: 80 | G14: =$X$14 -> 1250 | H14: =F14*G14 -> 100000 | L14: 417 авто-вышка | M14: 24 | N14: =$X$14 -> 1250 | O14: =M14*N14 -> 30000 | P14: 80 | Q14: =$X$14 -> 1250 | R14: =P14*Q14 -> 100000 | S14: 8 | T14: =$X$14 -> 1250 | U14: =S14*T14 -> 10000 | X14: =Y14 -> 1250 | Y14: =Z14/2 -> 1250 | Z14: 2500
B15: 434 м/автобус(газель) | C15: 218 | D15: =$X$15 -> 500 | E15: =C15*D15 -> 109000 | G15: =$X$15 -> 500 | H15: =F15*G15 -> 0 | L15: 434 м/автобус(газель) | M15: 218 | N15: =$X$15 -> 500 | O15: =M15*N15 -> 109000 | Q15: =$X$15 -> 500 | R15: =P15*Q15 -> 0 | T15: =$X$15 -> 500 | U15: =S15*T15 -> 0 | X15: =Y15 -> 500 | Y15: =Z15/2 -> 500 | Z15: 1000
A16: 301нет | B16: 498 бур-кран,автовышк | D16: =$X$16 -> 1750 | E16: =C16*D16 -> 0 | F16: 24 | G16: =$X$16 -> 1750 | H16: =F16*G16 -> 42000 | K16: 301нет | L16: 498 бур-кран,автовышк | N16: =$X$16 -> 1750 | O16: =M16*N16 -> 0 | P16: 24 | Q16: =$X$16 -> 1750 | R16: =P16*Q16 -> 42000 | T16: =$X$16 -> 1750 | U16: =S16*T16 -> 0 | X16: =Y16 -> 1750 | Y16: =Z16/2 -> 1750 | Z16: 3500
B17: 629 урал бур-кран | D17: =$X$17 -> 2000 | E17: =C17*D17 -> 0 | G17: =$X$17 -> 2000 | H17: =F17*G17 -> 0 | L17: 629 урал бур-кран | N17: =$X$17 -> 2000 | O17: =M17*N17 -> 0 | Q17: =$X$17 -> 2000 | R17: =P17*Q17 -> 0 | T17: =$X$17 -> 2000 | U17: =S17*T17 -> 0 | X17: =Y17 -> 2000 | Y17: =Z17/2 -> 2000 | Z17: 4000
B18: 703 бур-кран с автовышк | C18: 80 | D18: =$X$18 -> 2000 | E18: =C18*D18 -> 160000 | G18: =$X$18 -> 2000 | H18: =F18*G18 -> 0 | L18: 703 бур-кран с автовышк | M18: 80 | N18: =$X$18 -> 2000 | O18: =M18*N18 -> 160000 | Q18: =$X$18 -> 2000 | R18: =P18*Q18 -> 0 | T18: =$X$18 -> 2000 | U18: =S18*T18 -> 0 | X18: =Y18 -> 2000 | Y18: =Z18/2 -> 2000 | Z18: 4000
B19: 762 служеб.м/автобус | C19: 152 | D19: =$X$19 -> 500 | E19: =C19*D19 -> 76000 | G19: =$X$19 -> 500 | H19: =F19*G19 -> 0 | L19: 762 служеб.м/автобус | M19: 152 | N19: =$X$19 -> 500 | O19: =M19*N19 -> 76000 | Q19: =$X$19 -> 500 | R19: =P19*Q19 -> 0 | T19: =$X$19 -> 500 | U19: =S19*T19 -> 0 | X19: =Y19 -> 500 | Y19: =Z19/2 -> 500 | Z19: 1000
B20: 816 груз.-борт.с краном | C20: 124 | D20: =$X$20 -> 1250 | E20: =C20*D20 -> 155000 | G20: =$X$20 -> 1250 | H20: =F20*G20 -> 0 | L20: 816 груз.-борт.с краном | M20: =124-S20 -> 97 | N20: =$X$20 -> 1250 | O20: =M20*N20 -> 121250 | Q20: =$X$20 -> 1250 | R20: =P20*Q20 -> 0 | S20: 27 | T20: =$X$20 -> 1250 | U20: =S20*T20 -> 33750 | X20: =Y20 -> 1250 | Y20: =Z20/2 -> 1250 | Z20: 2500
A21: нет | B21: 887 бур-кран с автовышк | C21: 8 | D21: =$X$21 -> 1750 | E21: =C21*D21 -> 14000 | F21: 56 | G21: =$X$21 -> 1750 | H21: =F21*G21 -> 98000 | I21: 3000 было | K21: нет | L21: 887 бур-кран с автовышк | M21: 8 | N21: =$X$21 -> 1750 | O21: =M21*N21 -> 14000 | P21: 56 | Q21: =$X$21 -> 1750 | R21: =P21*Q21 -> 98000 | T21: =$X$21 -> 1750 | U21: =S21*T21 -> 0 | X21: =Y21 -> 1750 | Y21: =Z21/2 -> 1750 | Z21: 3500
B22: эксковатор KUBOTA KX-021+HANIX | C22: 38.5 | D22: =$X$21 -> 1750 | E22: =C22*D22 -> 67375 | G22: =$X$21 -> 1750 | H22: =F22*G22 -> 0 | L22: эксковатор KUBOTA KX-021+HANIX | M22: 38.5 | N22: =$X$21 -> 1750 | O22: =M22*N22 -> 67375 | Q22: =$X$21 -> 1750 | R22: =P22*Q22 -> 0 | T22: =$X$21 -> 1750 | U22: =S22*T22 -> 0 | X22: =Y22 -> 1000 | Y22: =Z22/2 -> 1000 | Z22: 2000
B23: ДТ 42 | D23: =$X$23 -> 1750 | E23: =C23*D23 -> 0 | G23: =$X$23 -> 1750 | H23: =F23*G23 -> 0 | L23: ДТ 42 | N23: =$X$23 -> 1750 | O23: =M23*N23 -> 0 | Q23: =$X$23 -> 1750 | R23: =P23*Q23 -> 0 | T23: =$X$23 -> 1750 | U23: =S23*T23 -> 0 | X23: =Y23 -> 1750 | Y23: =Z23/2 -> 1750 | Z23: 3500
B24: 295+прицеп | D24: =$X$24 -> 2500 | E24: =C24*D24 -> 0 | G24: =$X$24 -> 2500 | H24: =F24*G24 -> 0 | L24: 295+прицеп | M24: 53 | N24: =$X$24 -> 2500 | O24: =M24*N24 -> 132500 | P24: 26 | Q24: =$X$24 -> 2500 | R24: =P24*Q24 -> 65000 | S24: 28 | T24: =$X$24 -> 2500 | U24: =S24*T24 -> 70000 | X24: =Y24 -> 2500 | Y24: =Z24/2 -> 2500 | Z24: 5000
B25: генератор | E25: =C25*D25 -> 0 | H25: =F25*G25 -> 0 | L25: генератор | O25: =M25*N25 -> 0 | R25: =P25*Q25 -> 0 | U25: =S25*T25 -> 0
B26: бензопила | E26: =C26*D26 -> 0 | H26: =F26*G26 -> 0 | L26: бензопила | O26: =M26*N26 -> 0 | R26: =P26*Q26 -> 0 | U26: =S26*T26 -> 0
B27: теплопушка | E27: =C27*D27 -> 0 | H27: =F27*G27 -> 0 | L27: теплопушка | O27: =M27*N27 -> 0 | R27: =P27*Q27 -> 0 | U27: =S27*T27 -> 0
B28: Итого | C28: =SUM(C5:C27) -> 1092.5 | E28: =SUM(E5:E27) -> 1020375 | F28: =SUM(F5:F27) -> 352 | H28: =SUM(H5:H27) -> 566000 | L28: ИТОГО | M28: =SUM(M5:M27) -> 1090.5 | O28: =SUM(O5:O27) -> 1070125 | P28: =SUM(P5:P27) -> 240 | R28: =SUM(R5:R27) -> 389500 | S28: =SUM(S5:S27) -> 131 | U28: =SUM(U5:U27) -> 232750
L29: Итого факт | M29: =C28 -> 1092.5 | O29: =E28 -> 1020375 | P29: =F28 -> 352 | R29: =H28 -> 566000
B30: ИТОГО | L30: Итого разница | M30: =M28-M29 -> -2 | O30: =O28-O29 -> 49750 | P30: =P28-P29 -> -112 | R30: =R28-R29 -> -176500 | S30: =S28-S29 -> 131 | U30: =U28-U29 -> 232750
C34: МАРТ | E34: ВАРГА | F34: РАЗНИЦА
B35: Машина | C35: АМУР-ЭП | D35: Леонов | F35: ЭС+ | L35: ИТОГО за 1 кв-л | O35: ='01.26 (изм)'!N28+'02.26 (изм)'!M28+'03.26 (изм)'!O28 -> 3609087.5 | P35: =SUM(P12:P34) -> 666 | R35: ='01.26 (изм)'!Q28+'02.26 (изм)'!P28+'03.26 (изм)'!R28 -> 545000 | S35: =SUM(S12:S34) -> 325 | U35: ='01.26 (изм)'!T28+'02.26 (изм)'!S28+'03.26 (изм)'!U28 -> 629750
C36: час | D36: цена | E36: сумма | F36: час | G36: цена | H36: сумма
A37: 271 | B37: 110 буровая | D37: 3500 | E37: =C37*D37 -> 0 | G37: 3500 | H37: =F37*G37 -> 0
B38: 168 служебная | D38: 1000 | E38: =C38*D38 -> 0 | G38: 1000 | H38: =F38*G38 -> 0
B39: 185 груз.самосвал | C39: 136 | D39: 3500 | E39: =C39*D39 -> 476000 | G39: 3500 | H39: =F39*G39 -> 0
A40: нет | B40: 187 груз.с краном | C40: 64 | D40: 3500 | E40: =C40*D40 -> 224000 | G40: 3500 | H40: =F40*G40 -> 0
B41: 254 бур-кран+перевоз опор | C41: 88 | D41: 3500 | E41: =C41*D41 -> 308000 | G41: 3500 | H41: =F41*G41 -> 0
B42: 278 2-х каб.груз.-бортовой | D42: 1000 | E42: =C42*D42 -> 0 | G42: 1000 | H42: =F42*G42 -> 0
B43: 365 2-х кабинник | D43: 1000 | E43: =C43*D43 -> 0 | G43: 1000 | H43: =F43*G43 -> 0
B44: 344 2-х каб.груз.-бортовой | C44: 144 | D44: 1000 | E44: =C44*D44 -> 144000 | G44: 1000 | H44: =F44*G44 -> 0
...

Sheet 03.26
C2: МАРТ | E2: ВАРГА | F2: ФАКТ | M2: МАРТ | O2: ВАРГА | P2: общая
B3: Машина | C3: АМУР-ЭП | D3: Леонов | F3: ЭС+ | L3: Машина | M3: АМУР-ЭП | N3: Леонов | P3: ЭС+
C4: час | D4: цена | E4: сумма | F4: час | G4: цена | H4: сумма | M4: час | N4: цена | O4: сумма | P4: час | Q4: цена | R4: сумма
A5: 271 | B5: 110 буровая | D5: 3500 | E5: =C5*D5 -> 0 | F5: 152 | G5: 3500 | H5: =F5*G5 -> 532000 | K5: 271 | L5: 110 буровая | N5: 3500 | O5: =M5*N5 -> 0 | P5: 152 | Q5: 3500 | R5: =P5*Q5 -> 532000
B6: 168 служебная | C6: 180 | D6: 1000 | E6: =C6*D6 -> 180000 | G6: 1000 | H6: =F6*G6 -> 0 | L6: 168 служебная | M6: 180 | N6: 1000 | O6: =M6*N6 -> 180000 | Q6: 1000 | R6: =P6*Q6 -> 0
B7: 185 груз.самосвал | C7: 8 | D7: 3500 | E7: =C7*D7 -> 28000 | F7: 16 | G7: 3500 | H7: =F7*G7 -> 56000 | L7: 185 груз.самосвал | M7: 144 | N7: 3500 | O7: =M7*N7 -> 504000 | P7: 16 | Q7: 3500 | R7: =P7*Q7 -> 56000
A8: нет | B8: 187 груз.с краном | C8: 57 | D8: 3500 | E8: =C8*D8 -> 199500 | F8: 16 | G8: 3500 | H8: =F8*G8 -> 56000 | K8: нет | L8: 187 груз.с краном | M8: 121 | N8: 3500 | O8: =M8*N8 -> 423500 | P8: 16 | Q8: 3500 | R8: =P8*Q8 -> 56000
B9: 254 бур-кран+перевоз опор | C9: 35 | D9: 3500 | E9: =C9*D9 -> 122500 | G9: 3500 | H9: =F9*G9 -> 0 | L9: 254 бур-кран+перевоз опор | M9: 123 | N9: 3500 | O9: =M9*N9 -> 430500 | Q9: 3500 | R9: =P9*Q9 -> 0
B10: 278 2-х каб.груз.-бортовой | C10: 120 | D10: 1000 | E10: =C10*D10 -> 120000 | F10: 8 | G10: 1000 | H10: =F10*G10 -> 8000 | L10: 278 2-х каб.груз.-бортовой | M10: 120 | N10: 1000 | O10: =M10*N10 -> 120000 | P10: 8 | Q10: 1000 | R10: =P10*Q10 -> 8000
B11: 365 2-х кабинник | D11: 1000 | E11: =C11*D11 -> 0 | G11: 1000 | H11: =F11*G11 -> 0 | L11: 365 2-х кабинник | N11: 1000 | O11: =M11*N11 -> 0 | Q11: 1000 | R11: =P11*Q11 -> 0
B12: 344 2-х каб.груз.-бортовой | D12: 1000 | E12: =C12*D12 -> 0 | G12: 1000 | H12: =F12*G12 -> 0 | L12: 344 2-х каб.груз.-бортовой | M12: 144 | N12: 1000 | O12: =M12*N12 -> 144000 | Q12: 1000 | R12: =P12*Q12 -> 0
B13: 301+498 бур-кран с автовышк. | C13: 48 | D13: 3500 | E13: =C13*D13 -> 168000 | G13: 3500 | H13: =F13*G13 -> 0 | I13: 3000 было | L13: 301+498 бур-кран с автовышк. | M13: 88 | N13: 3500 | O13: =M13*N13 -> 308000 | Q13: 3500 | R13: =P13*Q13 -> 0
B14: 417 авто-вышка | C14: 24 | D14: 2500 | E14: =C14*D14 -> 60000 | F14: 80 | G14: 2500 | H14: =F14*G14 -> 200000 | L14: 417 авто-вышка | M14: 56 | N14: 2500 | O14: =M14*N14 -> 140000 | P14: 80 | Q14: 2500 | R14: =P14*Q14 -> 200000
B15: 434 м/автобус(газель) | C15: 218 | D15: 1000 | E15: =C15*D15 -> 218000 | G15: 1000 | H15: =F15*G15 -> 0 | L15: 434 м/автобус(газель) | M15: 218 | N15: 1000 | O15: =M15*N15 -> 218000 | Q15: 1000 | R15: =P15*Q15 -> 0
A16: 301нет | B16: 498 бур-кран,автовышк | D16: 3500 | E16: =C16*D16 -> 0 | F16: 24 | G16: 3500 | H16: =F16*G16 -> 84000 | K16: 301нет | L16: 498 бур-кран,автовышк | N16: 3500 | O16: =M16*N16 -> 0 | P16: 24 | Q16: 3500 | R16: =P16*Q16 -> 84000
B17: 629 урал бур-кран | D17: 4000 | E17: =C17*D17 -> 0 | G17: 4000 | H17: =F17*G17 -> 0 | L17: 629 урал бур-кран | N17: 4000 | O17: =M17*N17 -> 0 | Q17: 4000 | R17: =P17*Q17 -> 0
B18: 703 бур-кран с автовышк | C18: 80 | D18: 4000 | E18: =C18*D18 -> 320000 | G18: 4000 | H18: =F18*G18 -> 0 | L18: 703 бур-кран с автовышк | M18: 80 | N18: 4000 | O18: =M18*N18 -> 320000 | Q18: 4000 | R18: =P18*Q18 -> 0
B19: 762 служеб.м/автобус | C19: 152 | D19: 1000 | E19: =C19*D19 -> 152000 | G19: 1000 | H19: =F19*G19 -> 0 | L19: 762 служеб.м/автобус | M19: 152 | N19: 1000 | O19: =M19*N19 -> 152000 | Q19: 1000 | R19: =P19*Q19 -> 0
B20: 816 груз.-борт.с краном | C20: 124 | D20: 2500 | E20: =C20*D20 -> 310000 | G20: 2500 | H20: =F20*G20 -> 0 | L20: 816 груз.-борт.с краном | M20: 124 | N20: 2500 | O20: =M20*N20 -> 310000 | Q20: 2500 | R20: =P20*Q20 -> 0
A21: нет | B21: 887 бур-кран с автовышк | C21: 8 | D21: 3500 | E21: =C21*D21 -> 28000 | F21: 56 | G21: 3500 | H21: =F21*G21 -> 196000 | I21: 3000 было | K21: нет | L21: 887 бур-кран с автовышк | M21: 8 | N21: 3500 | O21: =M21*N21 -> 28000 | P21: 56 | Q21: 3500 | R21: =P21*Q21 -> 196000
B22: эксковатор KUBOTA KX-021+HANIX | C22: 38.5 | D22: 2000 | E22: =C22*D22 -> 77000 | G22: 2000 | H22: =F22*G22 -> 0 | L22: эксковатор KUBOTA KX-021+HANIX | M22: 38.5 | N22: 2000 | O22: =M22*N22 -> 77000 | Q22: 2000 | R22: =P22*Q22 -> 0
B23: ДТ 42 | D23: 3500 | E23: =C23*D23 -> 0 | G23: 3500 | H23: =F23*G23 -> 0 | L23: ДТ 42 | N23: 3500 | O23: =M23*N23 -> 0 | Q23: 3500 | R23: =P23*Q23 -> 0
B24: генератор | E24: =C24*D24 -> 0 | H24: =F24*G24 -> 0 | L24: генератор | O24: =M24*N24 -> 0 | R24: =P24*Q24 -> 0
B25: бензопила | E25: =C25*D25 -> 0 | H25: =F25*G25 -> 0 | L25: бензопила | O25: =M25*N25 -> 0 | R25: =P25*Q25 -> 0
B26: теплопушка | E26: =C26*D26 -> 0 | H26: =F26*G26 -> 0 | L26: теплопушка | O26: =M26*N26 -> 0 | R26: =P26*Q26 -> 0
B27: Итого | C27: =SUM(C5:C26) -> 1092.5 | E27: =SUM(E5:E26) -> 1983000 | F27: =SUM(F5:F26) -> 352 | H27: =SUM(H5:H26) -> 1132000 | L27: ИТОГО | M27: =SUM(M5:M26) -> 1596.5 | O27: =SUM(O5:O26) -> 3355000 | P27: =SUM(P5:P26) -> 352 | R27: =SUM(R5:R26) -> 1132000
L28: Итого факт | M28: 1092.5 | O28: 1983000 | P28: 352 | R28: 1132000
B29: ИТОГО | L29: Итого разница | M29: =M27-M28 -> 504 | O29: =O27-O28 -> 1372000 | P29: =P27-P28 -> 0 | R29: =R27-R28 -> 0
C33: МАРТ | E33: ВАРГА | F33: РАЗНИЦА
B34: Машина | C34: АМУР-ЭП | D34: Леонов | F34: ЭС+
C35: час | D35: цена | E35: сумма | F35: час | G35: цена | H35: сумма
A36: 271 | B36: 110 буровая | D36: 3500 | E36: =C36*D36 -> 0 | G36: 3500 | H36: =F36*G36 -> 0
B37: 168 служебная | D37: 1000 | E37: =C37*D37 -> 0 | G37: 1000 | H37: =F37*G37 -> 0
B38: 185 груз.самосвал | C38: 136 | D38: 3500 | E38: =C38*D38 -> 476000 | G38: 3500 | H38: =F38*G38 -> 0
A39: нет | B39: 187 груз.с краном | C39: 64 | D39: 3500 | E39: =C39*D39 -> 224000 | G39: 3500 | H39: =F39*G39 -> 0
B40: 254 бур-кран+перевоз опор | C40: 88 | D40: 3500 | E40: =C40*D40 -> 308000 | G40: 3500 | H40: =F40*G40 -> 0
B41: 278 2-х каб.груз.-бортовой | D41: 1000 | E41: =C41*D41 -> 0 | G41: 1000 | H41: =F41*G41 -> 0
B42: 365 2-х кабинник | D42: 1000 | E42: =C42*D42 -> 0 | G42: 1000 | H42: =F42*G42 -> 0
B43: 344 2-х каб.груз.-бортовой | C43: 144 | D43: 1000 | E43: =C43*D43 -> 144000 | G43: 1000 | H43: =F43*G43 -> 0
B44: 301+498 бур-кран с автовышк. | C44: 40 | D44: 3500 | E44: =C44*D44 -> 140000 | G44: 3500 | H44: =F44*G44 -> 0
...
